<?xml version="1.0" ?>

<robot name="robotino" xmlns:xacro="http://wiki.ros.org/xacro">
<xacro:include filename="$(find robotino_descrip)/urdf/robotino.gazebo"/>

<xacro:property name="camera_link" value="0.05" /> <!-- Size of square 'camera' box -->

  <link name="base_link">
    <inertial>
      <mass value="30"/>
      <origin xyz="0 0 0"/>
      <inertia ixx="1.0" ixy="0.0" ixz="0.0" iyy="1.0" iyz="0.0" izz="1.0"/>
    </inertial>
    <visual>
      <origin rpy="0 0 1.570795" xyz="0.01 0 0"/>
      <geometry>
        <mesh filename="package://robotino_descrip/meshes/parts/robotino_base.dae" scale="0.01 0.01 0.01"/>
      </geometry>
    </visual>
    <collision>
      <origin rpy="0 0 0" xyz="0 0 0.025"/>
      <geometry>
        <cylinder length="0.05" radius="0.18"/>
      </geometry>
    </collision>
  </link>
  
  <gazebo reference="base_link">
    <material>Gazebo/White</material>
    <turnGravityOff>false</turnGravityOff>
  </gazebo>
  <link name="wheel0_link">
    <inertial>
      <mass value="0.00001"/>
      <origin xyz="0 0 0"/>
      <inertia ixx="1.0" ixy="0.0" ixz="0.0" iyy="1.0" iyz="0.0" izz="1.0"/>
    </inertial>
    <visual>
      <origin rpy="0 0 0" xyz="0 0 0"/>
      <geometry>
        <mesh filename="package://robotino_descrip/meshes/parts/robotino_wheel.dae" scale="0.01 0.01 0.01"/>
      </geometry>
    </visual>
  </link>
  <gazebo reference="wheel0_link">
    <material>Gazebo/Yellow</material>
    <turnGravityOff>false</turnGravityOff>
  </gazebo>
  <joint name="wheel0_joint" type="continuous">
    <origin rpy="0 0 1.04719666667" xyz="0.065 0.11 0.04"/>
    <axis xyz="-1 0 0"/>
    <parent link="base_link"/>
    <child link="wheel0_link"/>
  </joint>
  <transmission name="wheel0_joint_trans">
    <type>transmissio_interface/SimpleTransmission</type>
    <joint name="wheel0_joint"/>
    <actuator name="wheel0_motor">
      <hardwareInterface>EffortJointInterface</hardwareInterface>
      <mechanicalReducation>1</mechanicalReducation>
    </actuator>
  </transmission>
  <link name="wheel1_link">
    <inertial>
      <mass value="0.00001"/>
      <origin xyz="0 0 0"/>
      <inertia ixx="1.0" ixy="0.0" ixz="0.0" iyy="1.0" iyz="0.0" izz="1.0"/>
    </inertial>
    <visual>
      <origin rpy="0 0 0" xyz="0 0 0"/>
      <geometry>
        <mesh filename="package://robotino_descrip/meshes/parts/robotino_wheel.dae" scale="0.01 0.01 0.01"/>
      </geometry>
    </visual>
  </link>
  <gazebo reference="wheel1_link">
    <material>Gazebo/Yellow</material>
    <turnGravityOff>false</turnGravityOff>
  </gazebo>
  <joint name="wheel1_joint" type="continuous">
    <origin rpy="0 0 0" xyz="-0.13 0 0.04"/>
    <axis xyz="1 0 0"/>
    <parent link="base_link"/>
    <child link="wheel1_link"/>
  </joint>
  <transmission name="wheel1_joint_trans">
    <type>transmissio_interface/SimpleTransmission</type>
    <joint name="wheel1_joint"/>
    <actuator name="wheel1_motor">
      <hardwareInterface>EffortJointInterface</hardwareInterface>
      <mechanicalReducation>1</mechanicalReducation>
    </actuator>
  </transmission>
  <link name="wheel2_link">
    <inertial>
      <mass value="0.00001"/>
      <origin xyz="0 0 0"/>
      <inertia ixx="1.0" ixy="0.0" ixz="0.0" iyy="1.0" iyz="0.0" izz="1.0"/>
    </inertial>
    <visual>
      <origin rpy="0 0 0" xyz="0 0 0"/>
      <geometry>
        <mesh filename="package://robotino_descrip/meshes/parts/robotino_wheel.dae" scale="0.01 0.01 0.01"/>
      </geometry>
    </visual>
  </link>
  <gazebo reference="wheel2_link">
    <material>Gazebo/Yellow</material>
    <turnGravityOff>false</turnGravityOff>
  </gazebo>
  <joint name="wheel2_joint" type="continuous">
    <origin rpy="0 0 -1.04719666667" xyz="0.065 -0.11 0.04"/>
    <axis xyz="-1 0 0"/>
    <parent link="base_link"/>
    <child link="wheel2_link"/>
  </joint>
  <transmission name="wheel2_joint_trans">
    <type>transmissio_interface/SimpleTransmission</type>
    <joint name="wheel2_joint"/>
    <actuator name="wheel2_motor">
      <hardwareInterface>EffortJointInterface</hardwareInterface>
      <mechanicalReducation>1</mechanicalReducation>
    </actuator>
  </transmission>
  <link name="command_bridge_link">
    <inertial>
      <mass value="0.00001"/>
      <origin xyz="0 0 0"/>
      <inertia ixx="1.0" ixy="0.0" ixz="0.0" iyy="1.0" iyz="0.0" izz="1.0"/>
    </inertial>
    <collision>
      <origin rpy="0 0 0" xyz="0 0 0"/>
      <geometry>
        <box size="0.25 0.11 0.16"/>
      </geometry>
    </collision>
  </link>
  <joint name="command_bridge_joint" type="fixed">
    <origin rpy="0 0 1.570795" xyz="-0.05 0 0.13"/>
    <parent link="base_link"/>
    <child link="command_bridge_link"/>
  </joint>
  <link name="anglebracketusb_link">
    <inertial>
      <mass value="0.00001"/>
      <origin xyz="0 0 0"/>
      <inertia ixx="1.0" ixy="0.0" ixz="0.0" iyy="1.0" iyz="0.0" izz="1.0"/>
    </inertial>
    <visual>
      <origin rpy="0 0 0" xyz="0 0 0"/>
      <geometry>
        <mesh filename="package://robotino_descrip/meshes/parts/angle_bracket_usb_hub.dae" scale="0.01 0.01 0.01"/>
      </geometry>
    </visual>
  </link>
  <joint name="anglebracketusb_joint" type="fixed">
    <origin rpy="0 0 1.570795" xyz="0.008 0 0.137"/>
    <parent link="base_link"/>
    <child link="anglebracketusb_link"/>
  </joint>
  <gazebo>
    <plugin filename="libgazebo_ros_planar_move.so" name="object_controller">
      <commandTopic>cmd_vel</commandTopic>
      <odometryTopic>odom</odometryTopic>
      <odometryFrame>odom</odometryFrame>
      <odometryRate>20</odometryRate>
      <robotBaseFrame>base_link</robotBaseFrame>
    </plugin>
    <plugin filename="libgazebo_ros_control.so" name="gazebo_ros_control"/>
  </gazebo>

  <!-- add platform -->
  <link name="platform_link">
    <inertial>
      <mass value="0.00001"/>
      <origin xyz="0 0 0"/>
      <inertia ixx="1.0" ixy="0.0" ixz="0.0" iyy="1.0" iyz="0.0" izz="1.0"/>
    </inertial>
    <visual>
      <origin xyz="0 0 0.29"/>
      <geometry>
        <cylinder length="0.58" radius="0.04"/>
      </geometry>
    </visual>
    <visual>
      <origin xyz="0 0 0.58"/>
      <geometry>
        <!-- actual length = 0.015 -->
        <cylinder length="0.02" radius="0.22"/>
      </geometry>
    </visual>
  </link>
  <joint name="platform_joint" type="fixed">
    <origin rpy="0 0 0" xyz="0.0 0.0 0.13"/>
    <parent link="base_link"/>
    <child link="platform_link"/>
  </joint>

  <link name="base_scan">
    <visual>
      <origin xyz="0 0 0.0" rpy="0 0 0"/>
      <geometry>
        <mesh filename="package://robotino_descrip/meshes/sensors/lds.stl" scale="0.001 0.001 0.001"/>
      </geometry>
    </visual>

    <collision>
      <origin xyz="0.015 0 -0.0065" rpy="0 0 0"/>
      <geometry>
        <cylinder length="0.0315" radius="0.055"/>
      </geometry>
    </collision>

    <inertial>
      <mass value="0.114" />
      <origin xyz="0 0 0" />
      <inertia ixx="0.001" ixy="0.0" ixz="0.0"
               iyy="0.001" iyz="0.0"
               izz="0.001" />
    </inertial>
  </link>

  <joint name="scan_joint" type="fixed">
    <parent link="base_link"/>
    <child link="base_scan"/>
    <origin xyz="-0.032 0 0.75" rpy="0 0 0"/>
  </joint>



<!-- first camera -->

  <!-- Camera -->
  <link name="camera_piller">
    <collision>
      <origin xyz="0 0.05 0.5" rpy="0 0 1.57"/>
      <geometry>
    <box size="${camera_link} ${camera_link} ${camera_link}"/>
      </geometry>
    </collision>

    <visual>
      <origin xyz="0.05 0.0 0.5" rpy="0 0 1.57"/>
      <geometry>
    <!-- <box size="${camera_link} ${camera_link} ${camera_link}"/> -->
        <mesh filename="package://robotino_descrip/meshes/sensors/camera.dae" scale="0.01 0.01 0.01"/>
    
      </geometry>
      <!-- <material name="red"/> -->
    </visual>

    <inertial>
      <mass value="1e-5" />
      <origin xyz="0 0 0" rpy="0 0 0"/>
      <inertia ixx="1e-6" ixy="0" ixz="0" iyy="1e-6" iyz="0" izz="1e-6" />
    </inertial>
  </link>

  <joint name="camera_joint" type="fixed">
    <axis xyz="0 1 0" />
    <origin xyz="0.0 0 0.0" rpy="0 0 0"/>
    <parent link="base_link"/>
    <child link="camera_piller"/>
  </joint>

<!-- second camera  -->

  <!-- Camera -->
  <link name="camera_base">
    <collision>
      <origin xyz="0.08 -0.05 0" rpy="0 0 2"/>
      <geometry>
    <box size="0.001 0.001 0.001"/>
      </geometry>
    </collision>

    <visual>
      <origin xyz="0.08 -0.05 0" rpy="0 0 2"/>
      <geometry>
    <!-- <box size="${camera_link} ${camera_link} ${camera_link}"/> -->
        <mesh filename="package://robotino_descrip/meshes/sensors/camera.dae" scale="0.01 0.01 0.01"/>
    
      </geometry>
      <!-- <material name="red"/> -->
    </visual>

    <inertial>
      <mass value="1e-5" />
      <origin xyz="0 0 0" rpy="0 0 0"/>
      <inertia ixx="1e-6" ixy="0" ixz="0" iyy="1e-6" iyz="0" izz="1e-6" />
    </inertial>
  </link>

  <joint name="camera2_joint" type="fixed">
    <axis xyz="0 1 0" />
    <origin xyz="0.0 0 0.0" rpy="0 0 0"/>
    <parent link="base_link"/>
    <child link="camera_base"/>
  </joint>

</robot>
