<?xml version="1.0" ?>
<!-- =================================================================================== -->
<!-- |    This document was autogenerated by xacro from /home/ros/catkin_ws/src/robotino_descrip/urdf/robotino_arm.xacro | -->
<!-- |    EDITING THIS FILE BY HAND IS NOT RECOMMENDED                                 | -->
<!-- =================================================================================== -->
<robot name="robotino">
    <!-- camera piller-->
    <gazebo reference="camera_piller">
        <sensor name="camera1" type="camera">
            <update_rate>30.0</update_rate>
            <camera name="head">
                <pose>0 0.05 0.5 0 0 0</pose>
                <horizontal_fov>1.3962634</horizontal_fov>
                <image>
                    <width>800</width>
                    <height>800</height>
                    <format>R8G8B8</format>
                </image>
                <clip>
                    <near>0.02</near>
                    <far>300</far>
                </clip>
                <noise>
                    <type>gaussian</type>
                    <!-- Noise is sampled independently per pixel on each frame.
               That pixel's noise value is added to each of its color
               channels, which at that point lie in the range [0,1]. -->
                    <mean>0.0</mean>
                    <stddev>0.007</stddev>
                </noise>
            </camera>
            <plugin filename="libgazebo_ros_camera.so" name="camera_controller">
                <alwaysOn>true</alwaysOn>
                <updateRate>0.0</updateRate>
                <cameraName>robotino/camera_piller</cameraName>
                <imageTopicName>image_raw</imageTopicName>
                <cameraInfoTopicName>camera_info</cameraInfoTopicName>
                <frameName>camera_piller</frameName>
                <hackBaseline>0.07</hackBaseline>
                <distortionK1>0.0</distortionK1>
                <distortionK2>0.0</distortionK2>
                <distortionK3>0.0</distortionK3>
                <distortionT1>0.0</distortionT1>
                <distortionT2>0.0</distortionT2>
            </plugin>
        </sensor>
        <plugin name="gazebo_ros_control">
            <robotNamespace>/</robotNamespace>
        </plugin>
    </gazebo>
    <!-- camera base -->
    <gazebo reference="camera_base">
        <sensor name="camera2" type="camera">
            <update_rate>30.0</update_rate>
            <camera name="head">
                <pose>0 -0.0 0.3 0 0 0</pose>
                <horizontal_fov>1.3962634</horizontal_fov>
                <image>
                    <width>800</width>
                    <height>800</height>
                    <format>R8G8B8</format>
                </image>
                <clip>
                    <near>0.02</near>
                    <far>300</far>
                </clip>
                <noise>
                    <type>gaussian</type>
                    <!-- Noise is sampled independently per pixel on each frame.
               That pixel's noise value is added to each of its color
               channels, which at that point lie in the range [0,1]. -->
                    <mean>0.0</mean>
                    <stddev>0.007</stddev>
                </noise>
            </camera>
            <plugin filename="libgazebo_ros_camera.so" name="camera_controller">
                <alwaysOn>true</alwaysOn>
                <updateRate>0.0</updateRate>
                <cameraName>robotino/camera_base</cameraName>
                <imageTopicName>image_raw</imageTopicName>
                <cameraInfoTopicName>camera_info</cameraInfoTopicName>
                <frameName>camera_base</frameName>
                <hackBaseline>0.07</hackBaseline>
                <distortionK1>0.0</distortionK1>
                <distortionK2>0.0</distortionK2>
                <distortionK3>0.0</distortionK3>
                <distortionT1>0.0</distortionT1>
                <distortionT2>0.0</distortionT2>
            </plugin>
        </sensor>
    </gazebo>
    <!-- LIDAR -->
    <gazebo reference="base_scan">
        <sensor name="libgazebo_ros_laser.so" type="ray">
            <pose>0 0 0 0 0 0</pose>
            <visualize>true</visualize>
            <update_rate>10</update_rate>
            <ray>
                <scan>
                    <horizontal>
                        <samples>720</samples>
                        <resolution>1</resolution>
                        <min_angle>-3.14</min_angle>
                        <max_angle>3.14</max_angle>
                    </horizontal>
                </scan>
                <range>
                    <min>0.12</min>
                    <max>3.5</max>
                    <resolution>0.01</resolution>
                </range>
                <noise>
                    <type>gaussian</type>
                    <mean>0.0</mean>
                    <stddev>0.01</stddev>
                </noise>
            </ray>
            <plugin filename="libgazebo_ros_laser.so" name="gazebo_ros_head_hokuyo_controller">
                <topicName>scan</topicName>
                <frameName>base_scan</frameName>
            </plugin>
        </sensor>
    </gazebo>
    <!-- Size of square 'camera' box -->
    <link name="base_link">
        <inertial>
            <mass value="30" />
            <origin xyz="0 0 0" rpy="0 0 0" />
            <inertia ixx="1.0" ixy="0.0" ixz="0.0" iyy="1.0" iyz="0.0" izz="1.0" />
        </inertial>
        <visual>
            <origin rpy="0 0 1.570795" xyz="0.01 0 0" />
            <geometry>
                <mesh filename="package://robotino_descrip/meshes/parts/robotino_base.dae" scale="0.01 0.01 0.01" />
            </geometry>
        </visual>
        <collision>
            <origin rpy="0 0 0" xyz="0 0 0.025" />
            <geometry>
                <cylinder length="0.05" radius="0.18" />
            </geometry>
        </collision>
    </link>
    <gazebo reference="base_link">
        <material>Gazebo/White</material>
        <turnGravityOff>false</turnGravityOff>
    </gazebo>
    <link name="wheel0_link">
        <inertial>
            <mass value="0.00001" />
            <origin xyz="0 0 0" />
            <inertia ixx="1.0" ixy="0.0" ixz="0.0" iyy="1.0" iyz="0.0" izz="1.0" />
        </inertial>
        <visual>
            <origin rpy="0 0 0" xyz="0 0 0" />
            <geometry>
                <mesh filename="package://robotino_descrip/meshes/parts/robotino_wheel.dae" scale="0.01 0.01 0.01" />
            </geometry>
        </visual>
    </link>
    <gazebo reference="wheel0_link">
        <material>Gazebo/Yellow</material>
        <turnGravityOff>false</turnGravityOff>
    </gazebo>
    <joint name="wheel0_joint" type="continuous">
        <origin rpy="0 0 1.04719666667" xyz="0.065 0.11 0.04" />
        <axis xyz="-1 0 0" />
        <parent link="base_link" />
        <child link="wheel0_link" />
    </joint>
    <transmission name="wheel0_joint_trans">
        <type>transmissio_interface/SimpleTransmission</type>
        <joint name="wheel0_joint" />
        <actuator name="wheel0_motor">
            <hardwareInterface>EffortJointInterface</hardwareInterface>
            <mechanicalReducation>1</mechanicalReducation>
        </actuator>
    </transmission>
    <link name="wheel1_link">
        <inertial>
            <mass value="0.00001" />
            <origin xyz="0 0 0" />
            <inertia ixx="1.0" ixy="0.0" ixz="0.0" iyy="1.0" iyz="0.0" izz="1.0" />
        </inertial>
        <visual>
            <origin rpy="0 0 0" xyz="0 0 0" />
            <geometry>
                <mesh filename="package://robotino_descrip/meshes/parts/robotino_wheel.dae" scale="0.01 0.01 0.01" />
            </geometry>
        </visual>
    </link>
    <gazebo reference="wheel1_link">
        <material>Gazebo/Yellow</material>
        <turnGravityOff>false</turnGravityOff>
    </gazebo>
    <joint name="wheel1_joint" type="continuous">
        <origin rpy="0 0 0" xyz="-0.13 0 0.04" />
        <axis xyz="1 0 0" />
        <parent link="base_link" />
        <child link="wheel1_link" />
    </joint>
    <transmission name="wheel1_joint_trans">
        <type>transmissio_interface/SimpleTransmission</type>
        <joint name="wheel1_joint" />
        <actuator name="wheel1_motor">
            <hardwareInterface>EffortJointInterface</hardwareInterface>
            <mechanicalReducation>1</mechanicalReducation>
        </actuator>
    </transmission>
    <link name="wheel2_link">
        <inertial>
            <mass value="0.00001" />
            <origin xyz="0 0 0" />
            <inertia ixx="1.0" ixy="0.0" ixz="0.0" iyy="1.0" iyz="0.0" izz="1.0" />
        </inertial>
        <visual>
            <origin rpy="0 0 0" xyz="0 0 0" />
            <geometry>
                <mesh filename="package://robotino_descrip/meshes/parts/robotino_wheel.dae" scale="0.01 0.01 0.01" />
            </geometry>
        </visual>
    </link>
    <gazebo reference="wheel2_link">
        <material>Gazebo/Yellow</material>
        <turnGravityOff>false</turnGravityOff>
    </gazebo>
    <joint name="wheel2_joint" type="continuous">
        <origin rpy="0 0 -1.04719666667" xyz="0.065 -0.11 0.04" />
        <axis xyz="-1 0 0" />
        <parent link="base_link" />
        <child link="wheel2_link" />
    </joint>
    <transmission name="wheel2_joint_trans">
        <type>transmissio_interface/SimpleTransmission</type>
        <joint name="wheel2_joint" />
        <actuator name="wheel2_motor">
            <hardwareInterface>EffortJointInterface</hardwareInterface>
            <mechanicalReducation>1</mechanicalReducation>
        </actuator>
    </transmission>
    <link name="command_bridge_link">
        <inertial>
            <mass value="0.00001" />
            <origin xyz="0 0 0" rpy="0 0 0" />
            <inertia ixx="1.0" ixy="0.0" ixz="0.0" iyy="1.0" iyz="0.0" izz="1.0" />
        </inertial>
        <collision>
            <origin rpy="0 0 0" xyz="0 0 0" />
            <geometry>
                <box size="0.25 0.11 0.16" />
            </geometry>
        </collision>
    </link>
    <joint name="command_bridge_joint" type="fixed">
        <origin rpy="0 0 1.570795" xyz="-0.05 0 0.13" />
        <parent link="base_link" />
        <child link="command_bridge_link" />
    </joint>
    <link name="anglebracketusb_link">
        <inertial>
            <mass value="0.00001" />
            <origin xyz="0 0 0" />
            <inertia ixx="1.0" ixy="0.0" ixz="0.0" iyy="1.0" iyz="0.0" izz="1.0" />
        </inertial>
        <visual>
            <origin rpy="0 0 0" xyz="0 0 0" />
            <geometry>
                <mesh filename="package://robotino_descrip/meshes/parts/angle_bracket_usb_hub.dae" scale="0.01 0.01 0.01" />
            </geometry>
        </visual>
    </link>
    <joint name="anglebracketusb_joint" type="fixed">
        <origin rpy="0 0 1.570795" xyz="0.008 0 0.137" />
        <parent link="base_link" />
        <child link="anglebracketusb_link" />
    </joint>
    <gazebo>
        <plugin filename="libgazebo_ros_planar_move.so" name="object_controller">
            <commandTopic>cmd_vel</commandTopic>
            <odometryTopic>odom</odometryTopic>
            <odometryFrame>odom</odometryFrame>
            <odometryRate>20</odometryRate>
            <robotBaseFrame>base_link</robotBaseFrame>
        </plugin>
        <plugin filename="libgazebo_ros_control.so" name="gazebo_ros_control" />
    </gazebo>
    <!-- add platform -->
    <link name="platform_link">
        <inertial>
            <mass value="0.00001" />
            <origin xyz="0 0 0" />
            <inertia ixx="1.0" ixy="0.0" ixz="0.0" iyy="1.0" iyz="0.0" izz="1.0" />
        </inertial>
        <visual>
            <origin xyz="0 0 0.29" />
            <geometry>
                <cylinder length="0.58" radius="0.04" />
            </geometry>
        </visual>
        <visual>
            <origin xyz="0 0 0.58" />
            <geometry>
                <!-- actual length = 0.015 -->
                <cylinder length="0.02" radius="0.22" />
            </geometry>
        </visual>
    </link>
    <joint name="platform_joint" type="fixed">
        <origin rpy="0 0 0" xyz="0.0 0.0 0.13" />
        <parent link="base_link" />
        <child link="platform_link" />
    </joint>
    <link name="base_scan">
        <visual>
            <origin rpy="0 0 0" xyz="0 0 0.0" />
            <geometry>
                <mesh filename="package://robotino_descrip/meshes/sensors/lds.stl" scale="0.001 0.001 0.001" />
            </geometry>
        </visual>
        <collision>
            <origin rpy="0 0 0" xyz="0.015 0 -0.0065" />
            <geometry>
                <cylinder length="0.0315" radius="0.055" />
            </geometry>
        </collision>
        <inertial>
            <mass value="0.114" />
            <origin xyz="0 0 0" rpy="0 0 0" />
            <inertia ixx="0.001" ixy="0.0" ixz="0.0" iyy="0.001" iyz="0.0" izz="0.001" />
        </inertial>
    </link>
    <joint name="scan_joint" type="fixed">
        <parent link="base_link" />
        <child link="base_scan" />
        <origin rpy="0 0 0" xyz="-0.032 0 0.75" />
    </joint>
    <!-- first camera -->
    <!-- Camera -->
    <link name="camera_piller">
        <collision>
            <origin rpy="0 0 1.57" xyz="0 0.05 0.5" />
            <geometry>
                <box size="0.05 0.05 0.05" />
            </geometry>
        </collision>
        <visual>
            <origin rpy="0 0 1.57" xyz="0.05 0.0 0.5" />
            <geometry>
                <!-- <box size="${camera_link} ${camera_link} ${camera_link}"/> -->
                <mesh filename="package://robotino_descrip/meshes/sensors/camera.dae" scale="0.01 0.01 0.01" />
            </geometry>
            <!-- <material name="red"/> -->
        </visual>
        <inertial>
            <mass value="1e-5" />
            <origin rpy="0 0 0" xyz="0 0 0" />
            <inertia ixx="1e-6" ixy="0" ixz="0" iyy="1e-6" iyz="0" izz="1e-6" />
        </inertial>
    </link>
    <joint name="camera_joint" type="fixed">
        <axis xyz="0 1 0" />
        <origin rpy="0 0 0" xyz="0.0 0 0.0" />
        <parent link="base_link" />
        <child link="camera_piller" />
    </joint>
    <!-- second camera  -->
    <!-- Camera -->
    <link name="camera_base">
        <collision>
            <origin rpy="0 0 2" xyz="0.08 -0.05 0" />
            <geometry>
                <box size="0.001 0.001 0.001" />
            </geometry>
        </collision>
        <visual>
            <origin rpy="0 0 2" xyz="0.08 -0.05 0" />
            <geometry>
                <!-- <box size="${camera_link} ${camera_link} ${camera_link}"/> -->
                <mesh filename="package://robotino_descrip/meshes/sensors/camera.dae" scale="0.01 0.01 0.01" />
            </geometry>
            <!-- <material name="red"/> -->
        </visual>
        <inertial>
            <mass value="1e-5" />
            <origin rpy="0 0 0" xyz="0 0 0" />
            <inertia ixx="1e-6" ixy="0" ixz="0" iyy="1e-6" iyz="0" izz="1e-6" />
        </inertial>
    </link>
    <joint name="camera2_joint" type="fixed">
        <axis xyz="0 1 0" />
        <origin rpy="0 0 0" xyz="0.0 0 0.0" />
        <parent link="base_link" />
        <child link="camera_base" />
    </joint>
    <!-- robotic arm embedding -->
    <link name="base_link_arm">
        <inertial>
            <origin rpy="0 0 0" xyz="-0.0370127633091683 0.019070320751848 0.144702744937737" />
            <mass value="0.0485300603816627" />
            <inertia ixx="1.21348391060661E-05" ixy="-1.83170561820002E-07" ixz="2.01283221627451E-09" iyy="1.03176250980936E-05" iyz="8.98306870809956E-08" izz="1.3705089569295E-05" />
        </inertial>
        <visual>
            <origin rpy="0 0 0" xyz="0 0 0" />
            <geometry>
                <mesh filename="package://robotino_arm_v2_udf/meshes/base_link.STL" />
            </geometry>
            <material name="">
                <color rgba="0.792156862745098 0.819607843137255 0.933333333333333 1" />
            </material>
        </visual>
        <collision>
            <origin rpy="0 0 0" xyz="0 0 0" />
            <geometry>
                <mesh filename="package://robotino_arm_v2_udf/meshes/base_link.STL" />
            </geometry>
        </collision>
    </link>
    <!-- <link name="world" /> -->
    <joint name="fix" type="fixed">
        <parent link="base_link" />
        <child link="base_link_arm" />
        <origin rpy="-1.57 0 1.57" xyz="0.12 0.05 -0.05" />
    </joint>
    <link name="L1">
        <inertial>
            <origin rpy="0 0 0" xyz="0.0218613397170321 -0.0643083979647138 -0.0106559317352375" />
            <mass value="0.0123298942666567" />
            <inertia ixx="1.86723406131852E-05" ixy="-3.47242222560863E-10" ixz="1.18024925877695E-09" iyy="6.09881410181813E-06" iyz="-8.12828881398934E-07" izz="2.15012069724987E-05" />
        </inertial>
        <visual>
            <origin rpy="0 0 0" xyz="0 0 0" />
            <geometry>
                <mesh filename="package://robotino_arm_v2_udf/meshes/L1.STL" />
            </geometry>
            <material name="">
                <color rgba="0.792156862745098 0.819607843137255 0.933333333333333 1" />
            </material>
        </visual>
        <collision>
            <origin rpy="0 0 0" xyz="0 0 0" />
            <geometry>
                <mesh filename="package://robotino_arm_v2_udf/meshes/L1.STL" />
            </geometry>
        </collision>
    </link>
    <joint name="J1" type="revolute">
        <origin rpy="1.5325 -1.6571E-05 3.1412" xyz="-0.015177 -0.14501 0.0031767" />
        <parent link="base_link_arm" />
        <child link="L1" />
        <axis xyz="1 0 -0.00043232" />
        <limit effort="10" lower="0" upper="1.8" velocity="0.2" />
    </joint>
    <link name="L2">
        <inertial>
            <origin rpy="0 0 0" xyz="0.0218828627980577 0.002734641651011 0.0384853882508786" />
            <mass value="0.0879186008437833" />
            <inertia ixx="2.08913128379421E-05" ixy="2.66064625040772E-08" ixz="3.62172435526932E-07" iyy="2.46188638028951E-05" iyz="-6.75708643034757E-07" izz="1.5509544710887E-05" />
        </inertial>
        <visual>
            <origin rpy="0 0 0" xyz="0 0 0" />
            <geometry>
                <mesh filename="package://robotino_arm_v2_udf/meshes/L2.STL" />
            </geometry>
            <material name="">
                <color rgba="0.792156862745098 0.819607843137255 0.933333333333333 1" />
            </material>
        </visual>
        <collision>
            <origin rpy="0 0 0" xyz="0 0 0" />
            <geometry>
                <mesh filename="package://robotino_arm_v2_udf/meshes/L2.STL" />
            </geometry>
        </collision>
    </link>
    <joint name="J2" type="revolute">
        <origin rpy="1.7 0.00048802 -0.00042872" xyz="0 -0.13842 -0.0076949" />
        <parent link="L1" />
        <child link="L2" />
        <axis xyz="1 0 -0.00043232" />
        <limit effort="10" lower="-1.8" upper="1.8" velocity="0.2" />
    </joint>
    <link name="L3">
        <inertial>
            <origin rpy="0 0 0" xyz="0.0210324963278343 0.00345434614035189 0.0443927660933133" />
            <mass value="0.0470068003445836" />
            <inertia ixx="8.27072638092313E-06" ixy="1.82174461954528E-07" ixz="-1.31004150631563E-08" iyy="1.15598328470863E-05" iyz="1.42985163489217E-07" izz="1.33891638883011E-05" />
        </inertial>
        <visual>
            <origin rpy="0 0 0" xyz="0 0 0" />
            <geometry>
                <mesh filename="package://robotino_arm_v2_udf/meshes/L3.STL" />
            </geometry>
            <material name="">
                <color rgba="0.792156862745098 0.819607843137255 0.933333333333333 1" />
            </material>
        </visual>
        <collision>
            <origin rpy="0 0 0" xyz="0 0 0" />
            <geometry>
                <mesh filename="package://robotino_arm_v2_udf/meshes/L3.STL" />
            </geometry>
        </collision>
    </link>
    <joint name="J3" type="revolute">
        <origin rpy="0.0042565 0 0" xyz="3.3285E-05 0.0056816 0.076991" />
        <parent link="L2" />
        <child link="L3" />
        <axis xyz="1 0 -0.00043232" />
        <limit effort="10" lower="-1.8" upper="1.8" velocity="0.2" />
    </joint>
    <link name="GR">
        <inertial>
            <origin rpy="0 0 0" xyz="-0.00443543982926508 -4.33266183444692E-05 -0.0353860660374369" />
            <mass value="0.0182294853598354" />
            <inertia ixx="1.0394691303712E-05" ixy="4.83375753942016E-10" ixz="9.97321914417416E-08" iyy="6.1120326767523E-06" iyz="7.72174800352589E-10" izz="5.70322869333795E-06" />
        </inertial>
        <visual>
            <origin rpy="0 0 0" xyz="0 0 0" />
            <geometry>
                <mesh filename="package://robotino_arm_v2_udf/meshes/GR.STL" />
            </geometry>
            <material name="">
                <color rgba="0.792156862745098 0.819607843137255 0.933333333333333 1" />
            </material>
        </visual>
        <collision>
            <origin rpy="0 0 0" xyz="0 0 0" />
            <geometry>
                <mesh filename="package://robotino_arm_v2_udf/meshes/GR.STL" />
            </geometry>
        </collision>
    </link>
    <joint name="J4" type="revolute">
        <origin rpy="3.0636 0.029147 -0.0022426" xyz="0.0094213 0.0036281 0.046465" />
        <parent link="L3" />
        <child link="GR" />
        <axis xyz="0 1 0" />
        <limit effort="10" lower="-1.8" upper="1.8" velocity="0.2" />
    </joint>
    <link name="GL">
        <inertial>
            <origin rpy="0 0 0" xyz="-0.00437064923464174 4.60766456037431E-05 -0.0358117241638067" />
            <mass value="0.0180904804143949" />
            <inertia ixx="1.04915012930938E-05" ixy="-9.96819798756622E-10" ixz="1.62170559104411E-07" iyy="6.34402248985625E-06" iyz="-1.9482740956521E-09" izz="5.68223727875759E-06" />
        </inertial>
        <visual>
            <origin rpy="0 0 0" xyz="0 0 0" />
            <geometry>
                <mesh filename="package://robotino_arm_v2_udf/meshes/GL.STL" />
            </geometry>
            <material name="">
                <color rgba="0.792156862745098 0.819607843137255 0.933333333333333 1" />
            </material>
        </visual>
        <collision>
            <origin rpy="0 0 0" xyz="0 0 0" />
            <geometry>
                <mesh filename="package://robotino_arm_v2_udf/meshes/GL.STL" />
            </geometry>
        </collision>
    </link>
    <joint name="J5" type="revolute">
        <origin rpy="-3.0636 0.040018 -3.1384" xyz="0.03407 0.0036281 0.046454" />
        <parent link="L3" />
        <child link="GL" />
        <axis xyz="0 1 0" />
        <limit effort="10" lower="-1.8" upper="1.8" velocity="0.2" />
        <mimic joint="J4" multiplier="1" offset="0" />
    </joint>
    <transmission name="trans_J1">
        <type>transmission_interface/SimpleTransmission</type>
        <joint name="J1">
            <hardwareInterface>hardware_interface/PositionJointInterface</hardwareInterface>
        </joint>
        <actuator name="J1_motor">
            <hardwareInterface>hardware_interface/PositionJointInterface</hardwareInterface>
            <mechanicalReduction>1</mechanicalReduction>
        </actuator>
    </transmission>
    <transmission name="trans_J2">
        <type>transmission_interface/SimpleTransmission</type>
        <joint name="J2">
            <hardwareInterface>hardware_interface/PositionJointInterface</hardwareInterface>
        </joint>
        <actuator name="J2_motor">
            <hardwareInterface>hardware_interface/PositionJointInterface</hardwareInterface>
            <mechanicalReduction>1</mechanicalReduction>
        </actuator>
    </transmission>
    <transmission name="trans_J3">
        <type>transmission_interface/SimpleTransmission</type>
        <joint name="J3">
            <hardwareInterface>hardware_interface/PositionJointInterface</hardwareInterface>
        </joint>
        <actuator name="J3_motor">
            <hardwareInterface>hardware_interface/PositionJointInterface</hardwareInterface>
            <mechanicalReduction>1</mechanicalReduction>
        </actuator>
    </transmission>
    <transmission name="trans_J4">
        <type>transmission_interface/SimpleTransmission</type>
        <joint name="J4">
            <hardwareInterface>hardware_interface/PositionJointInterface</hardwareInterface>
        </joint>
        <actuator name="J4_motor">
            <hardwareInterface>hardware_interface/PositionJointInterface</hardwareInterface>
            <mechanicalReduction>1</mechanicalReduction>
        </actuator>
    </transmission>
    <transmission name="trans_J5">
        <type>transmission_interface/SimpleTransmission</type>
        <joint name="J5">
            <hardwareInterface>hardware_interface/EffortJointInterface</hardwareInterface>
        </joint>
        <actuator name="J5_motor">
            <hardwareInterface>hardware_interface/EffortJointInterface</hardwareInterface>
            <mechanicalReduction>1</mechanicalReduction>
        </actuator>
    </transmission>
    <!-- <gazebo>
        <plugin name="gazebo_ros_control" filename="libgazebo_ros_control.so">
            <robotNamespace>/</robotNamespace>
        </plugin>
    </gazebo> -->
    <transmission name="trans_wheel0_joint">
        <type>transmission_interface/SimpleTransmission</type>
        <joint name="wheel0_joint">
            <hardwareInterface>hardware_interface/EffortJointInterface</hardwareInterface>
        </joint>
        <actuator name="wheel0_joint_motor">
            <hardwareInterface>hardware_interface/EffortJointInterface</hardwareInterface>
            <mechanicalReduction>1</mechanicalReduction>
        </actuator>
    </transmission>
    <transmission name="trans_wheel1_joint">
        <type>transmission_interface/SimpleTransmission</type>
        <joint name="wheel1_joint">
            <hardwareInterface>hardware_interface/EffortJointInterface</hardwareInterface>
        </joint>
        <actuator name="wheel1_joint_motor">
            <hardwareInterface>hardware_interface/EffortJointInterface</hardwareInterface>
            <mechanicalReduction>1</mechanicalReduction>
        </actuator>
    </transmission>
    <transmission name="trans_wheel2_joint">
        <type>transmission_interface/SimpleTransmission</type>
        <joint name="wheel2_joint">
            <hardwareInterface>hardware_interface/EffortJointInterface</hardwareInterface>
        </joint>
        <actuator name="wheel2_joint_motor">
            <hardwareInterface>hardware_interface/EffortJointInterface</hardwareInterface>
            <mechanicalReduction>1</mechanicalReduction>
        </actuator>
    </transmission>
</robot>
